Workbook
Name Slicer_Product_Category: #N/A
Name Slicer_Product_Category1: #N/A
Name Slicer_Product_Category2: #N/A
Name Slicer_Review_Score: #N/A

Sheet Pivot Units Monthly
A3: Row Labels | B3: Units Sold | L3: Highest
A4: Sales_Unit_January | B4: 498306 | L4: Lowest
A5: Sales_Unit_February | B5: 507661
A6: Sales_Unit_March | B6: 506739
A7: Sales_Unit_April | B7: 503823
A8: Sales_Unit_May | B8: 487194
A9: Sales_Unit_June | B9: 491653
A10: Sales_Unit_July | B10: 507011
A11: Sales_Unit_August | B11: 504569
A12: Sales_Unit_September | B12: 491934
A13: Sales_Unit_October | B13: 514798
A14: Sales_Unit_November | B14: 505838
A15: Sales_Unit_December | B15: 500386
A16: Grand Total | B16: 6019912
A19: Sum of Value | B19: Column Labels
A20: Row Labels | B20: Books | C20: Clothing | D20: Electronics | E20: Health | F20: Home & Kitchen | G20: Sports | H20: Toys | I20: Grand Total
A21: Sales_Unit_January | B21: 77932 | C21: 60966 | D21: 76347 | E21: 67644 | F21: 57844 | G21: 77737 | H21: 79836 | I21: 498306
A22: Sales_Unit_February | B22: 80079 | C22: 67911 | D22: 72472 | E22: 67432 | F22: 57252 | G22: 82244 | H22: 80271 | I22: 507661
A23: Sales_Unit_March | B23: 76998 | C23: 76796 | D23: 70708 | E23: 67602 | F23: 62667 | G23: 75109 | H23: 76859 | I23: 506739
A24: Sales_Unit_April | B24: 74699 | C24: 70088 | D24: 73158 | E24: 72925 | F24: 65388 | G24: 74287 | H24: 73278 | I24: 503823
A25: Sales_Unit_May | B25: 79051 | C25: 61643 | D25: 72169 | E25: 69178 | F25: 59766 | G25: 73467 | H25: 71920 | I25: 487194
A26: Sales_Unit_June | B26: 76644 | C26: 63123 | D26: 70060 | E26: 63926 | F26: 63169 | G26: 75641 | H26: 79090 | I26: 491653
A27: Sales_Unit_July | B27: 79114 | C27: 66105 | D27: 72223 | E27: 75256 | F27: 60129 | G27: 77082 | H27: 77102 | I27: 507011
A28: Sales_Unit_August | B28: 78108 | C28: 74422 | D28: 65754 | E28: 69126 | F28: 65042 | G28: 73912 | H28: 78205 | I28: 504569
A29: Sales_Unit_September | B29: 77211 | C29: 72675 | D29: 69914 | E29: 64581 | F29: 58135 | G29: 79209 | H29: 70209 | I29: 491934
A30: Sales_Unit_October | B30: 83504 | C30: 68806 | D30: 70148 | E30: 72613 | F30: 64876 | G30: 80187 | H30: 74664 | I30: 514798
A31: Sales_Unit_November | B31: 76557 | C31: 71683 | D31: 68148 | E31: 72500 | F31: 66281 | G31: 74270 | H31: 76399 | I31: 505838
A32: Sales_Unit_December | B32: 78332 | C32: 72318 | D32: 64019 | E32: 71631 | F32: 61592 | G32: 73226 | H32: 79268 | I32: 500386
A33: Grand Total | B33: 938229 | C33: 826536 | D33: 845120 | E33: 834414 | F33: 742141 | G33: 916371 | H33: 917101 | I33: 6019912
B36: KPI ON MONTHLY SALES TREND
B38: • Annual Highest sales on October
B39: • Annual Lowest sales on May
B41: • Books Tops in October & Low in April
B42: • Clothing Tops in March & Low in January
B43: • Electronics Tops in January & Low in December
B44: • Health Tops in July & Low in June
B45: • Home & Kitchen Tops in November & Low in February
B46: • Sports Tops in February & Low in December
B47: • Toys Tops in February & Low in September
B49: Seasonality Patterns Found are:
...

Sheet Pivot Review
A1: Review_Score | B1: 4.5
A3: Row Labels | B3: Sum of Annual_Revenue
A4: Books | B4: 1.49669e+08
A5: Clothing | B5: 1.2049186e+08
A6: Electronics | B6: 45741243
A7: Health | B7: 86552213
A8: Home & Kitchen | B8: 46678768
A9: Sports | B9: 1.2021904e+08
A10: Toys | B10: 65354061
A11: Grand Total | B11: 6.3470618e+08
A15: Row Labels | B15: Average of Review_Score | C15: Average of Annual_Revenue | E15: Product_Category | F15: Average of Review_Score | G15: Average of Annual_Revenue
A16: Books | B16: 3.0967532 | C16: 1537550.7 | E16: Books | F16: 3.0967532 | G16: 1537550.7
A17: Clothing | B17: 2.9521429 | C17: 1337559.4 | E17: Clothing | F17: 2.9521429 | G17: 1337559.4
A18: Electronics | B18: 3.1434783 | C18: 1461410.8 | E18: Electronics | F18: 3.1434783 | G18: 1461410.8
A19: Health | B19: 3.005036 | C19: 1595229.2 | E19: Health | F19: 3.005036 | G19: 1595229.2
A20: Home & Kitchen | B20: 3.0352 | C20: 1426924 | E20: Home & Kitchen | F20: 3.0352 | G20: 1426924
A21: Sports | B21: 3.0915033 | C21: 1520580.6 | E21: Sports | F21: 3.0915033 | G21: 1520580.6
A22: Toys | B22: 2.8708609 | C22: 1524749.6 | E22: Toys | F22: 2.8708609 | G22: 1524749.6
A23: Grand Total | B23: 3.0276 | C23: 1488704.2
E27: KPI From Comparison
E28: Correlation is:
E29: =CORREL(B16:B22,C16:C22) -> 0.10700162
B42: Review & Revenue Correlation
B43: Correlation value is: 0.1070016
B44: Positive Correlation
B45: So Higher Reviews = Higher Revenue

Sheet Dashboard

Sheet Power Units Cleaned
A1: Product_ID | B1: Product_Name | C1: Product_Category | D1: Product_Price | E1: Review_Score | F1: Review_Count | G1: Total_Units_Sold | H1: Annual_Revenue | I1: Month | J1: Value
A2: 1 | B2: Product_1 | C2: Clothing | D2: 190.4 | E2: 1.7 | F2: 220 | G2: 6421 | H2: 1222558.4 | I2: Sales_Unit_January | J2: 479
A3: 1 | B3: Product_1 | C3: Clothing | D3: 190.4 | E3: 1.7 | F3: 220 | G3: 6421 | H3: 1222558.4 | I3: Sales_Unit_February | J3: 449
A4: 1 | B4: Product_1 | C4: Clothing | D4: 190.4 | E4: 1.7 | F4: 220 | G4: 6421 | H4: 1222558.4 | I4: Sales_Unit_March | J4: 92
A5: 1 | B5: Product_1 | C5: Clothing | D5: 190.4 | E5: 1.7 | F5: 220 | G5: 6421 | H5: 1222558.4 | I5: Sales_Unit_April | J5: 784
A6: 1 | B6: Product_1 | C6: Clothing | D6: 190.4 | E6: 1.7 | F6: 220 | G6: 6421 | H6: 1222558.4 | I6: Sales_Unit_May | J6: 604
A7: 1 | B7: Product_1 | C7: Clothing | D7: 190.4 | E7: 1.7 | F7: 220 | G7: 6421 | H7: 1222558.4 | I7: Sales_Unit_June | J7: 904
A8: 1 | B8: Product_1 | C8: Clothing | D8: 190.4 | E8: 1.7 | F8: 220 | G8: 6421 | H8: 1222558.4 | I8: Sales_Unit_July | J8: 446
A9: 1 | B9: Product_1 | C9: Clothing | D9: 190.4 | E9: 1.7 | F9: 220 | G9: 6421 | H9: 1222558.4 | I9: Sales_Unit_August | J9: 603
A10: 1 | B10: Product_1 | C10: Clothing | D10: 190.4 | E10: 1.7 | F10: 220 | G10: 6421 | H10: 1222558.4 | I10: Sales_Unit_September | J10: 807
A11: 1 | B11: Product_1 | C11: Clothing | D11: 190.4 | E11: 1.7 | F11: 220 | G11: 6421 | H11: 1222558.4 | I11: Sales_Unit_October | J11: 252
A12: 1 | B12: Product_1 | C12: Clothing | D12: 190.4 | E12: 1.7 | F12: 220 | G12: 6421 | H12: 1222558.4 | I12: Sales_Unit_November | J12: 695
A13: 1 | B13: Product_1 | C13: Clothing | D13: 190.4 | E13: 1.7 | F13: 220 | G13: 6421 | H13: 1222558.4 | I13: Sales_Unit_December | J13: 306
... A12001: 1000 | B12001: Product_1000 | C12001: Toys | D12001: 225.77 | E12001: 2.1 | F12001: 114 | G12001: 7486 | H12001: 1690114.2 | I12001: Sales_Unit_December | J12001: 110

Sheet ecommerce_sales_analysis
A1: Product_ID | B1: Product_Name | C1: Product_Category | D1: Product_Price | E1: Review_Score | F1: Review_Count | G1: Sales_Unit_January | H1: Sales_Unit_February | I1: Sales_Unit_March | J1: Sales_Unit_April | K1: Sales_Unit_May | L1: Sales_Unit_June | M1: Sales_Unit_July | N1: Sales_Unit_August | O1: Sales_Unit_September | P1: Sales_Unit_October | Q1: Sales_Unit_November | R1: Sales_Unit_December | S1: Total_Units_Sold | T1: Annual_Revenue
A2: 1 | B2: Product_1 | C2: Clothing | D2: 190.4 | E2: 1.7 | F2: 220 | G2: 479 | H2: 449 | I2: 92 | J2: 784 | K2: 604 | L2: 904 | M2: 446 | N2: 603 | O2: 807 | P2: 252 | Q2: 695 | R2: 306 | S2: =SUM(G2:R2) -> 6421 | T2: =(S2*D2) -> 1222558.4
A3: 2 | B3: Product_2 | C3: Home & Kitchen | D3: 475.6 | E3: 3.2 | F3: 903 | G3: 21 | H3: 989 | I3: 861 | J3: 863 | K3: 524 | L3: 128 | M3: 610 | N3: 436 | O3: 176 | P3: 294 | Q3: 772 | R3: 353 | S3: =SUM(G3:R3) -> 6027 | T3: =(S3*D3) -> 2866441.2
A4: 3 | B4: Product_3 | C4: Toys | D4: 367.34 | E4: 4.5 | F4: 163 | G4: 348 | H4: 558 | I4: 567 | J4: 143 | K4: 771 | L4: 409 | M4: 290 | N4: 828 | O4: 340 | P4: 667 | Q4: 267 | R4: 392 | S4: =SUM(G4:R4) -> 5580 | T4: =(S4*D4) -> 2049757.2
A5: 4 | B5: Product_4 | C5: Toys | D5: 301.34 | E5: 3.9 | F5: 951 | G5: 725 | H5: 678 | I5: 59 | J5: 15 | K5: 937 | L5: 421 | M5: 670 | N5: 933 | O5: 56 | P5: 157 | Q5: 168 | R5: 203 | S5: =SUM(G5:R5) -> 5022 | T5: =(S5*D5) -> 1513329.5
A6: 5 | B6: Product_5 | C6: Books | D6: 82.23 | E6: 4.2 | F6: 220 | G6: 682 | H6: 451 | I6: 649 | J6: 301 | K6: 620 | L6: 293 | M6: 411 | N6: 258 | O6: 854 | P6: 548 | Q6: 770 | R6: 257 | S6: =SUM(G6:R6) -> 6094 | T6: =(S6*D6) -> 501109.62
A7: 6 | B7: Product_6 | C7: Toys | D7: 82.22 | E7: 3.6 | F7: 270 | G7: 834 | H7: 288 | I7: 38 | J7: 422 | K7: 329 | L7: 245 | M7: 614 | N7: 979 | O7: 851 | P7: 630 | Q7: 738 | R7: 485 | S7: =SUM(G7:R7) -> 6453 | T7: =(S7*D7) -> 530565.66
A8: 7 | B8: Product_7 | C8: Electronics | D8: 33.75 | E8: 3.8 | F8: 632 | G8: 565 | H8: 140 | I8: 539 | J8: 244 | K8: 188 | L8: 700 | M8: 896 | N8: 965 | O8: 447 | P8: 66 | Q8: 32 | R8: 516 | S8: =SUM(G8:R8) -> 5298 | T8: =(S8*D8) -> 178807.5
A9: 8 | B9: Product_8 | C9: Electronics | D9: 433.76 | E9: 4.4 | F9: 906 | G9: 905 | H9: 83 | I9: 48 | J9: 926 | K9: 94 | L9: 555 | M9: 280 | N9: 102 | O9: 202 | P9: 753 | Q9: 376 | R9: 445 | S9: =SUM(G9:R9) -> 4769 | T9: =(S9*D9) -> 2068601.4
A10: 9 | B10: Product_9 | C10: Electronics | D10: 302.55 | E10: 2 | F10: 848 | G10: 809 | H10: 693 | I10: 419 | J10: 106 | K10: 616 | L10: 85 | M10: 42 | N10: 992 | O10: 696 | P10: 298 | Q10: 213 | R10: 708 | S10: =SUM(G10:R10) -> 5677 | T10: =(S10*D10) -> 1717576.4
A11: 10 | B11: Product_10 | C11: Clothing | D11: 355.5 | E11: 3 | F11: 400 | G11: 319 | H11: 390 | I11: 636 | J11: 87 | K11: 7 | L11: 555 | M11: 485 | N11: 566 | O11: 632 | P11: 462 | Q11: 561 | R11: 179 | S11: =SUM(G11:R11) -> 4879 | T11: =(S11*D11) -> 1734484.5
A12: 11 | B12: Product_11 | C12: Toys | D12: 15.19 | E12: 1.9 | F12: 182 | G12: 125 | H12: 590 | I12: 12 | J12: 128 | K12: 66 | L12: 841 | M12: 595 | N12: 768 | O12: 737 | P12: 724 | Q12: 439 | R12: 341 | S12: =SUM(G12:R12) -> 5366 | T12: =(S12*D12) -> 81509.54
A13: 12 | B13: Product_12 | C13: Health | D13: 485.11 | E13: 5 | F13: 991 | G13: 276 | H13: 214 | I13: 991 | J13: 906 | K13: 495 | L13: 374 | M13: 962 | N13: 100 | O13: 201 | P13: 819 | Q13: 491 | R13: 132 | S13: =SUM(G13:R13) -> 5961 | T13: =(S13*D13) -> 2891740.7
... A1001: 1000 | B1001: Product_1000 | C1001: Toys | D1001: 225.77 | E1001: 2.1 | F1001: 114 | G1001: 890 | H1001: 903 | I1001: 983 | J1001: 769 | K1001: 134 | L1001: 704 | M1001: 648 | N1001: 400 | O1001: 495 | P1001: 839 | Q1001: 611 | R1001: 110 | S1001: =SUM(G1001:R1001) -> 7486 | T1001: =(S1001*D1001) -> 1690114.2
D1002: Total = | G1002: =SUM(G2:G1001) -> 498306 | H1002: =SUM(H2:H1001) -> 507661 | I1002: =SUM(I2:I1001) -> 506739 | J1002: =SUM(J2:J1001) -> 503823 | K1002: =SUM(K2:K1001) -> 487194 | L1002: =SUM(L2:L1001) -> 491653 | M1002: =SUM(M2:M1001) -> 507011 | N1002: =SUM(N2:N1001) -> 504569 | ... T1002: =SUM(T2:T1001) -> 1.4887042e+09

Sheet Goal Seek
A1: Product_ID | B1: Product_Name | C1: Product_Category | D1: Product_Price | E1: Total_Units_Sold | F1: Annual_Revenue | G1: New Price | H1: Old Units | I1: New Revenue | J1: 10% Revenue | K1: 15% Revenue | L1: Old Price | M1: New Units | N1: New Revenue | O1: Old Price | P1: New Units | Q1: New Revenue
A2: 1 | B2: Product_1 | C2: Clothing | D2: 190.4 | E2: 6421 | F2: =(D2*E2) -> 1222558.4 | G2: 209.44 | H2: 6421 | I2: =(G2*H2) -> 1344814.2 | J2: =(F2*1.1) -> 1344814.2 | K2: =(F2*1.15) -> 1405942.2 | L2: 190.4 | M2: 7384.15 | N2: =L2*M2 -> 1405942.2 | O2: 233.60847 | P2: 6421 | Q2: =O2*P2 -> 1500000
A3: 2 | B3: Product_2 | C3: Home & Kitchen | D3: 475.6 | E3: 6027 | F3: =(D3*E3) -> 2866441.2 | G3: 523.16 | H3: 6027 | I3: =(G3*H3) -> 3153085.3 | J3: =(F3*1.1) -> 3153085.3 | K3: =(F3*1.15) -> 3296407.4 | L3: 475.6 | M3: 6931.05 | N3: =L3*M3 -> 3296407.4 | O3: =O2-L2 -> 43.208472
A4: 3 | B4: Product_3 | C4: Toys | D4: 367.34 | E4: 5580 | F4: =(D4*E4) -> 2049757.2 | G4: 367.34 | H4: 5580 | J4: =(F4*1.1) -> 2254732.9 | K4: =(F4*1.15) -> 2357220.8 | L4: 367.34 | M4: 5580
A5: 4 | B5: Product_4 | C5: Toys | D5: 301.34 | E5: 5022 | F5: =(D5*E5) -> 1513329.5 | G5: 301.34 | H5: 5022 | J5: =(F5*1.1) -> 1664662.4 | K5: =(F5*1.15) -> 1740328.9 | L5: 301.34 | M5: 5022 | O5: 190.4 | P5: 7878.1513 | Q5: =(O5*P5) -> 1500000
A6: 5 | B6: Product_5 | C6: Books | D6: 82.23 | E6: 6094 | F6: =(D6*E6) -> 501109.62 | G6: 82.23 | H6: 6094 | J6: =(F6*1.1) -> 551220.58 | K6: =(F6*1.15) -> 576276.06 | L6: 82.23 | M6: 6094 | P6: =P5-P2 -> 1457.1513
A7: 6 | B7: Product_6 | C7: Toys | D7: 82.22 | E7: 6453 | F7: =(D7*E7) -> 530565.66 | G7: 82.22 | H7: 6453 | J7: =(F7*1.1) -> 583622.23 | K7: =(F7*1.15) -> 610150.51 | L7: 82.22 | M7: 6453
A8: 7 | B8: Product_7 | C8: Electronics | D8: 33.75 | E8: 5298 | F8: =(D8*E8) -> 178807.5 | G8: 33.75 | H8: 5298 | J8: =(F8*1.1) -> 196688.25 | K8: =(F8*1.15) -> 205628.62 | L8: 33.75 | M8: 5298
A9: 8 | B9: Product_8 | C9: Electronics | D9: 433.76 | E9: 4769 | F9: =(D9*E9) -> 2068601.4 | G9: 433.76 | H9: 4769 | J9: =(F9*1.1) -> 2275461.6 | K9: =(F9*1.15) -> 2378891.7 | L9: 433.76 | M9: 4769
A10: 9 | B10: Product_9 | C10: Electronics | D10: 302.55 | E10: 5677 | F10: =(D10*E10) -> 1717576.4 | G10: 302.55 | H10: 5677 | J10: =(F10*1.1) -> 1889334 | K10: =(F10*1.15) -> 1975212.8 | L10: 302.55 | M10: 5677
A11: 10 | B11: Product_10 | C11: Clothing | D11: 355.5 | E11: 4879 | F11: =(D11*E11) -> 1734484.5 | G11: 355.5 | H11: 4879 | J11: =(F11*1.1) -> 1907933 | K11: =(F11*1.15) -> 1994657.2 | L11: 355.5 | M11: 4879
A12: 11 | B12: Product_11 | C12: Toys | D12: 15.19 | E12: 5366 | F12: =(D12*E12) -> 81509.54 | G12: 15.19 | H12: 5366 | J12: =(F12*1.1) -> 89660.494 | K12: =(F12*1.15) -> 93735.971 | L12: 15.19 | M12: 5366
A13: 12 | B13: Product_12 | C13: Health | D13: 485.11 | E13: 5961 | F13: =(D13*E13) -> 2891740.7 | G13: 485.11 | H13: 5961 | J13: =(F13*1.1) -> 3180914.8 | K13: =(F13*1.15) -> 3325501.8 | L13: 485.11 | M13: 5961
A14: 13 | B14: Product_13 | C14: Electronics | D14: 417.06 | E14: 5218 | F14: =(D14*E14) -> 2176219.1 | G14: 417.06 | H14: 5218 | J14: =(F14*1.1) -> 2393841 | K14: =(F14*1.15) -> 2502651.9 | L14: 417.06 | M14: 5218
A15: 14 | B15: Product_14 | C15: Books | D15: 110.11 | E15: 4201 | F15: =(D15*E15) -> 462572.11 | G15: 110.11 | H15: 4201 | J15: =(F15*1.1) -> 508829.32 | K15: =(F15*1.15) -> 531957.93 | L15: 110.11 | M15: 4201
A16: 15 | B16: Product_15 | C16: Clothing | D16: 95 | E16: 5864 | F16: =(D16*E16) -> 557080 | G16: 95 | H16: 5864 | J16: =(F16*1.1) -> 612788 | K16: =(F16*1.15) -> 640642 | L16: 95 | M16: 5864
A17: 16 | B17: Product_16 | C17: Books | D17: 95.79 | E17: 6042 | F17: =(D17*E17) -> 578763.18 | G17: 95.79 | H17: 6042 | J17: =(F17*1.1) -> 636639.5 | K17: =(F17*1.15) -> 665577.66 | L17: 95.79 | M17: 6042
A18: 17 | B18: Product_17 | C18: Toys | D18: 155.6 | E18: 5259 | F18: =(D18*E18) -> 818300.4 | G18: 155.6 | H18: 5259 | J18: =(F18*1.1) -> 900130.44 | K18: =(F18*1.15) -> 941045.46 | L18: 155.6 | M18: 5259
... A1001: 1000 | B1001: Product_1000 | C1001: Toys | D1001: 225.77 | E1001: 7486 | F1001: =(D1001*E1001) -> 1690114.2 | G1001: 225.77 | H1001: 7486 | J1001: =(F1001*1.1) -> 1859125.6 | K1001: =(F1001*1.15) -> 1943631.4 | L1001: 225.77 | M1001: 7486
D1002: Total = | F1002: =SUM(F2:F1001) -> 1.4887042e+09 | J1002: =(F1002*1.1) -> 1.6375746e+09 | K1002: =(F1002*1.15) -> 1.7120098e+09

Sheet Sheet2
A3: Row Labels | B3: Sum of Annual_Revenue | C3: Sum of Total_Units_Sold | D3: Average of Review_Score
A4: Books | B4: 2.3678281e+08 | C4: 938229 | D4: 3.0967532
A5: Sports | B5: 2.3264883e+08 | C5: 916371 | D5: 3.0915033
A6: Toys | B6: 2.3023718e+08 | C6: 917101 | D6: 2.8708609
A7: Health | B7: 2.2173685e+08 | C7: 834414 | D7: 3.005036
A8: Electronics | B8: 2.0167468e+08 | C8: 845120 | D8: 3.1434783
A9: Clothing | B9: 1.8725832e+08 | C9: 826536 | D9: 2.9521429
A10: Home & Kitchen | B10: 1.7836551e+08 | C10: 742141 | D10: 3.0352
A11: Grand Total | B11: 1.4887042e+09 | C11: 6019912 | D11: 3.0276

Sheet Sheet4
A1: Product_ID | B1: Product_Name | C1: Product_Category | D1: Product_Price | E1: Review_Score | F1: Review_Count | G1: Sales_Amount_January | H1: Sales_Amount_February | I1: Sales_Amount_March | J1: Sales_Amount_April | K1: Sales_Amount_May | L1: Sales_Amount_June | M1: Sales_Amount_July | N1: Sales_Amount_August | O1: Sales_Amount_September | P1: Sales_Amount_October | Q1: Sales_Amount_November | R1: Sales_Amount_December | S1: Annual_Revenue | T1: Average_Revenue_PerProduct | U1: Revenue_Contribution
A2: 5 | B2: Product_5 | C2: Books | D2: 82.23 | E2: 4.2 | F2: 220 | G2: 56080.86 | H2: 37085.73 | I2: 53367.27 | J2: 24751.23 | K2: 50982.6 | L2: 24093.39 | M2: 33796.53 | N2: 21215.34 | O2: 70224.42 | P2: 45062.04 | Q2: 63317.1 | R2: 21133.11 | S2: 501109.62 | T2: 41759.135 | U2: 0.033660792
A3: 14 | B3: Product_14 | C3: Books | D3: 110.11 | E3: 1.2 | F3: 729 | G3: 22352.33 | H3: 23563.54 | I3: 11011 | J3: 37437.4 | K3: 40190.15 | L3: 41511.47 | M3: 5505.5 | N3: 89409.32 | O3: 39859.82 | P3: 6056.05 | Q3: 53733.68 | R3: 91941.85 | S3: 462572.11 | T3: 38547.676 | U3: 0.031072131
A4: 16 | B4: Product_16 | C4: Books | D4: 95.79 | E4: 4.7 | F4: 582 | G4: 65137.2 | H4: 12165.33 | I4: 8142.15 | J4: 31227.54 | K4: 49810.8 | L4: 62838.24 | M4: 20020.11 | N4: 90234.18 | O4: 43392.87 | P4: 79984.65 | Q4: 90521.55 | R4: 25288.56 | S4: 578763.18 | T4: 48230.265 | U4: 0.038876977
A5: 19 | B5: Product_19 | C5: Books | D5: 218.81 | E5: 4.7 | F5: 813 | G5: 152072.95 | H5: 166076.79 | I5: 73738.97 | J5: 66737.05 | K5: 58203.46 | L5: 64111.33 | M5: 111155.48 | N5: 5470.25 | O5: 212464.51 | P5: 162357.02 | Q5: 187738.98 | R5: 89712.1 | S5: 1349838.9 | T5: 112486.57 | U5: 0.090672069
A6: 22 | B6: Product_22 | C6: Books | D6: 74.05 | E6: 2.2 | F6: 619 | G6: 54278.65 | H6: 58573.55 | I6: 28287.1 | J6: 53316 | K6: 37617.4 | L6: 19623.25 | M6: 42949 | N6: 37395.25 | O6: 1629.1 | P6: 6738.55 | Q6: 1184.8 | R6: 47095.8 | S6: 388688.45 | T6: 32390.704 | U6: 0.02610918
A7: 23 | B7: Product_23 | C7: Books | D7: 149.61 | E7: 4.7 | F7: 596 | G7: 45182.22 | H7: 50418.57 | I7: 127916.55 | J7: 33512.64 | K7: 44434.17 | L7: 17803.59 | M7: 116097.36 | N7: 27079.41 | O7: 23039.94 | P7: 118191.9 | Q7: 8228.55 | R7: 111459.45 | S7: 723364.35 | T7: 60280.363 | U7: 0.048590201
A8: 29 | B8: Product_29 | C8: Books | D8: 298.25 | E8: 2.3 | F8: 196 | G8: 33404 | H8: 64720.25 | I8: 8947.5 | J8: 294372.75 | K8: 163441 | L8: 16702 | M8: 123475.5 | N8: 293179.75 | O8: 95440 | P8: 292583.25 | Q8: 248740.5 | R8: 33404 | S8: 1668410.5 | T8: 139034.21 | U8: 0.11207132
A9: 30 | B9: Product_30 | C9: Books | D9: 27.99 | E9: 4.3 | F9: 690 | G9: 13631.13 | H9: 16038.27 | I9: 10468.26 | J9: 5038.2 | K9: 2043.27 | L9: 10664.19 | M9: 251.91 | N9: 8788.86 | O9: 10888.11 | P9: 25722.81 | Q9: 615.78 | R9: 25191 | S9: 129341.79 | T9: 10778.483 | U9: 0.008688213
A10: 42 | B10: Product_42 | C10: Books | D10: 250.11 | E10: 4.2 | F10: 472 | G10: 35015.4 | H10: 20258.91 | I10: 59276.07 | J10: 204339.87 | K10: 207841.41 | L10: 203839.65 | M10: 97042.68 | N10: 5752.53 | O10: 43769.25 | P10: 209592.18 | Q10: 195836.13 | R10: 236353.95 | S10: 1518918 | T10: 126576.5 | U10: 0.10202954
A11: 55 | B11: Product_55 | C11: Books | D11: 300.96 | E11: 5 | F11: 314 | G11: 30998.88 | H11: 241369.92 | I11: 147169.44 | J11: 197128.8 | K11: 236855.52 | L11: 221807.52 | M11: 36717.12 | N11: 238661.28 | O11: 280795.68 | P11: 109549.44 | Q11: 168537.6 | R11: 174857.76 | S11: 2084449 | T11: 173704.08 | U11: 0.14001767
A12: 59 | B12: Product_59 | C12: Books | D12: 27.39 | E12: 2.9 | F12: 131 | G12: 25773.99 | H12: 21665.49 | I12: 4930.2 | J12: 794.31 | K12: 13475.88 | L12: 24459.27 | M12: 11503.8 | N12: 8737.41 | O12: 15064.5 | P12: 24760.56 | Q12: 13119.81 | R12: 1588.62 | S12: 165873.84 | T12: 13822.82 | U12: 0.011142163
A13: 68 | B13: Product_68 | C13: Books | D13: 402.09 | E13: 1.4 | F13: 853 | G13: 234418.47 | H13: 268596.12 | I13: 148773.3 | J13: 119420.73 | K13: 233614.29 | L13: 103337.13 | M13: 299959.14 | N13: 345395.31 | O13: 170486.16 | P13: 71974.11 | Q13: 23321.22 | R13: 69963.66 | S13: 2089259.6 | T13: 174104.97 | U13: 0.14034082
... A1001: 1000 | B1001: Product_1000 | C1001: Toys | D1001: 225.77 | E1001: 2.1 | F1001: 114 | G1001: 200935.3 | H1001: 203870.31 | I1001: 221931.91 | J1001: 173617.13 | K1001: 30253.18 | L1001: 158942.08 | M1001: 146298.96 | N1001: 90308 | O1001: 111756.15 | P1001: 189421.03 | Q1001: 137945.47 | R1001: 24834.7 | S1001: 1690114.2 | T1001: 140842.85 | U1001: 0.11352922

Sheet Revenue Pivot
A3: Row Labels | B3: Sum of Annual_Revenue
A4: Books | B4: 2.3678281e+08 | H4: KPI Best Performance Category
A5: Clothing | B5: 1.8725832e+08 | H5: Best Revenue Category : | K5: Books
A6: Electronics | B6: 2.0167468e+08 | H6: Least Revenue Category : | K6: Home & Kitchen
A7: Health | B7: 2.2173685e+08
A8: Home & Kitchen | B8: 1.7836551e+08 | H8: Highest Units Sold : | K8: Books
A9: Sports | B9: 2.3264883e+08 | H9: Lowest Units Sold: | K9: Home & Kitchen
A10: Toys | B10: 2.3023718e+08
A11: Grand Total | B11: 1.4887042e+09 | H11: Highest Review Score : | K11: Electronics
H12: Lowest Review Score : | K12: Toys
H14: Future Insights Suggestions
A15: Row Labels | B15: Sum of Total_Units_Sold | H15: Electronics Products
A16: Books | B16: 938229 | H16: As Review Score is High; Good to introduce attractive offers to increase sale.
A17: Clothing | B17: 826536
A18: Electronics | B18: 845120 | H18: Home & Kitchen Products
A19: Health | B19: 834414 | H19: Review score is good; But lowest sale; can improve sales by introducing attractive offers.
A20: Home & Kitchen | B20: 742141
A21: Sports | B21: 916371 | H21: Toys
A22: Toys | B22: 917101 | H22: Even Sales is good, Review score is low; Introducing better products and quality would help continuity sale.
A23: Grand Total | B23: 6019912
H25: As Books are at top performance, introduce combo offers with books & other product categories.
A28: Row Labels | B28: Average of Review_Score
A29: Books | B29: 3.0967532
A30: Clothing | B30: 2.9521429
A31: Electronics | B31: 3.1434783
A32: Health | B32: 3.005036
A33: Home & Kitchen | B33: 3.0352
A34: Sports | B34: 3.0915033
A35: Toys | B35: 2.8708609
A36: Grand Total | B36: 3.0276

Sheet Sheet7
A1: Product_ID | B1: Product_Name | C1: Product_Category | D1: Product_Price | E1: Review_Score | F1: Review_Count | G1: Annual_Revenue | H1: Average_Revenue_PerProduct | I1: Revenue_Contribution | J1: Month | K1: Value
A2: 990 | B2: Product_990 | C2: Electronics | D2: 410.46 | E2: 3.9 | F2: 806 | G2: 3150280.5 | H2: 262523.38 | I2: 0.21161226 | J2: May | K2: 402250.8
A3: 989 | B3: Product_989 | C3: Electronics | D3: 126.97 | E3: 2.7 | F3: 575 | G3: 680432.23 | H3: 56702.686 | I3: 0.045706342 | J3: May | K3: 95608.41
A4: 976 | B4: Product_976 | C4: Electronics | D4: 134.82 | E4: 4.8 | F4: 48 | G4: 789640.74 | H4: 65803.395 | I4: 0.053042152 | J4: May | K4: 70241.22
A5: 967 | B5: Product_967 | C5: Electronics | D5: 360.93 | E5: 1.7 | F5: 82 | G5: 2245345.5 | H5: 187112.13 | I5: 0.1508255 | J5: May | K5: 234965.43
A6: 958 | B6: Product_958 | C6: Electronics | D6: 28.25 | E6: 2.7 | F6: 704 | G6: 139329 | H6: 11610.75 | I6: 0.009359079 | J6: May | K6: 24436.25
A7: 950 | B7: Product_950 | C7: Electronics | D7: 300.72 | E7: 2.7 | F7: 587 | G7: 1372185.4 | H7: 114348.78 | I7: 0.092173138 | J7: May | K7: 39394.32
A8: 949 | B8: Product_949 | C8: Electronics | D8: 437.58 | E8: 2.3 | F8: 102 | G8: 2724373.1 | H8: 227031.09 | I8: 0.18300298 | J8: May | K8: 52509.6
A9: 947 | B9: Product_947 | C9: Electronics | D9: 72.76 | E9: 2.8 | F9: 762 | G9: 434668.24 | H9: 36222.353 | I9: 0.029197758 | J9: May | K9: 6111.84
A10: 942 | B10: Product_942 | C10: Electronics | D10: 279.32 | E10: 2.3 | F10: 748 | G10: 2087637.7 | H10: 173969.81 | I10: 0.14023187 | J10: May | K10: 143849.8
A11: 940 | B11: Product_940 | C11: Electronics | D11: 290.38 | E11: 1.3 | F11: 304 | G11: 1728632.1 | H11: 144052.68 | I11: 0.11611656 | J11: May | K11: 226206.02
A12: 937 | B12: Product_937 | C12: Electronics | D12: 14.1 | E12: 2.1 | F12: 883 | G12: 119271.9 | H12: 9939.325 | I12: 0.0080117932 | J12: May | K12: 10349.4
A13: 935 | B13: Product_935 | C13: Electronics | D13: 89.98 | E13: 3.7 | F13: 582 | G13: 451069.74 | H13: 37589.145 | I13: 0.030299488 | J13: May | K13: 86560.76
... A139: 13 | B139: Product_13 | C139: Electronics | D139: 417.06 | E139: 4.8 | F139: 618 | G139: 2176219.1 | H139: 181351.59 | I139: 0.1461821 | J139: May | K139: 79241.4

Sheet Montly Revenue Pivot
A3: Sum of Value | B3: Column Labels
A4: Row Labels | B4: Books | C4: Clothing | D4: Electronics | E4: Health | F4: Home & Kitchen | G4: Sports | H4: Toys | I4: Grand Total
A5: May | B5: 20609637 | C5: 14414174 | D5: 16572710 | E5: 18773000 | F5: 14147352 | G5: 19240938 | H5: 18157506 | I5: 1.2191532e+08
A6: Jan | B6: 19485930 | C6: 13436026 | D6: 18110208 | E6: 18045325 | F6: 14038194 | G6: 19055982 | H6: 19829068 | I6: 1.2200073e+08
A7: Feb | B7: 19957692 | C7: 16420644 | D7: 16775556 | E7: 17615619 | F7: 13298978 | G7: 21129564 | H7: 20414926 | I7: 1.2561298e+08
A8: Mar | B8: 20162438 | C8: 17012233 | D8: 16927993 | E8: 17980689 | F8: 14498643 | G8: 18612263 | H8: 19327888 | I8: 1.2452215e+08
A9: Apr | B9: 18956014 | C9: 16403848 | D9: 17839635 | E9: 19133269 | F9: 16433015 | G9: 19044637 | H9: 18821009 | I9: 1.2663143e+08
A10: Jun | B10: 18964253 | C10: 14118954 | D10: 16821514 | E10: 16400221 | F10: 14524429 | G10: 19109222 | H10: 19683657 | I10: 1.1962225e+08 | J10: Lowest
A11: Jul | B11: 20429338 | C11: 14605377 | D11: 16973996 | E11: 20455211 | F11: 14442993 | G11: 18729060 | H11: 18761948 | I11: 1.2439792e+08
A12: aug | B12: 18868303 | C12: 16583879 | D12: 15471865 | E12: 18360092 | F12: 16470170 | G12: 17796406 | H12: 19531864 | I12: 1.2308258e+08
A13: Sep | B13: 19109771 | C13: 16208454 | D13: 17190807 | E13: 16634508 | F13: 14098117 | G13: 20509356 | H13: 17748211 | I13: 1.2149922e+08
A14: Oct | B14: 21504710 | C14: 15565661 | D14: 17210047 | E14: 20046905 | F14: 15366885 | G14: 21070604 | H14: 18335781 | I14: 1.2910059e+08 | J14: Highest
A15: Nov | B15: 19100834 | C15: 15584495 | D15: 16479786 | E15: 19658149 | F15: 16101031 | G15: 19358695 | H15: 19334162 | I15: 1.2561715e+08
A16: Dec | B16: 19633885 | C16: 16904576 | D16: 15300569 | E16: 18633865 | F16: 14945698 | G16: 18992106 | H16: 20291163 | I16: 1.2470186e+08
A17: Grand Total | B17: 2.3678281e+08 | C17: 1.8725832e+08 | D17: 2.0167468e+08 | E17: 2.2173685e+08 | F17: 1.7836551e+08 | G17: 2.3264883e+08 | H17: 2.3023718e+08 | I17: 1.4887042e+09
A39: Row Labels | B39: Sum of Value
A40: May | B40: 1.2191532e+08
A41: Jan | B41: 1.2200073e+08
A42: Feb | B42: 1.2561298e+08
A43: Mar | B43: 1.2452215e+08
A44: Apr | B44: 1.2663143e+08
A45: Jun | B45: 1.1962225e+08
A46: Jul | B46: 1.2439792e+08
A47: aug | B47: 1.2308258e+08
A48: Sep | B48: 1.2149922e+08
A49: Oct | B49: 1.2910059e+08
A50: Nov | B50: 1.2561715e+08
A51: Dec | B51: 1.2470186e+08
A52: Grand Total | B52: 1.4887042e+09

Sheet Power Cleaned Revenue
A1: Product_ID | B1: Product_Name | C1: Product_Category | D1: Product_Price | E1: Review_Score | F1: Review_Count | G1: Annual_Revenue | H1: Average_Revenue_PerProduct | I1: Revenue_Contribution | J1: Month | K1: Value
A2: 1 | B2: Product_1 | C2: Clothing | D2: 190.4 | E2: 1.7 | F2: 220 | G2: 1222558.4 | H2: 101879.87 | I2: 0.082122319 | J2: Sales_Amount_January | K2: 91201.6
A3: 1 | B3: Product_1 | C3: Clothing | D3: 190.4 | E3: 1.7 | F3: 220 | G3: 1222558.4 | H3: 101879.87 | I3: 0.082122319 | J3: Sales_Amount_February | K3: 85489.6
A4: 1 | B4: Product_1 | C4: Clothing | D4: 190.4 | E4: 1.7 | F4: 220 | G4: 1222558.4 | H4: 101879.87 | I4: 0.082122319 | J4: Sales_Amount_March | K4: 17516.8
A5: 1 | B5: Product_1 | C5: Clothing | D5: 190.4 | E5: 1.7 | F5: 220 | G5: 1222558.4 | H5: 101879.87 | I5: 0.082122319 | J5: Sales_Amount_April | K5: 149273.6
A6: 1 | B6: Product_1 | C6: Clothing | D6: 190.4 | E6: 1.7 | F6: 220 | G6: 1222558.4 | H6: 101879.87 | I6: 0.082122319 | J6: Sales_Amount_May | K6: 115001.6
A7: 1 | B7: Product_1 | C7: Clothing | D7: 190.4 | E7: 1.7 | F7: 220 | G7: 1222558.4 | H7: 101879.87 | I7: 0.082122319 | J7: Sales_Amount_June | K7: 172121.6
A8: 1 | B8: Product_1 | C8: Clothing | D8: 190.4 | E8: 1.7 | F8: 220 | G8: 1222558.4 | H8: 101879.87 | I8: 0.082122319 | J8: Sales_Amount_July | K8: 84918.4
A9: 1 | B9: Product_1 | C9: Clothing | D9: 190.4 | E9: 1.7 | F9: 220 | G9: 1222558.4 | H9: 101879.87 | I9: 0.082122319 | J9: Sales_Amount_August | K9: 114811.2
A10: 1 | B10: Product_1 | C10: Clothing | D10: 190.4 | E10: 1.7 | F10: 220 | G10: 1222558.4 | H10: 101879.87 | I10: 0.082122319 | J10: Sales_Amount_September | K10: 153652.8
A11: 1 | B11: Product_1 | C11: Clothing | D11: 190.4 | E11: 1.7 | F11: 220 | G11: 1222558.4 | H11: 101879.87 | I11: 0.082122319 | J11: Sales_Amount_October | K11: 47980.8
A12: 1 | B12: Product_1 | C12: Clothing | D12: 190.4 | E12: 1.7 | F12: 220 | G12: 1222558.4 | H12: 101879.87 | I12: 0.082122319 | J12: Sales_Amount_November | K12: 132328
A13: 1 | B13: Product_1 | C13: Clothing | D13: 190.4 | E13: 1.7 | F13: 220 | G13: 1222558.4 | H13: 101879.87 | I13: 0.082122319 | J13: Sales_Amount_December | K13: 58262.4
... A12001: 1000 | B12001: Product_1000 | C12001: Toys | D12001: 225.77 | E12001: 2.1 | F12001: 114 | G12001: 1690114.2 | H12001: 140842.85 | I12001: 0.11352922 | J12001: Sales_Amount_December | K12001: 24834.7

Sheet Sheet10

Sheet Revenue Calculations
A1: Product_ID | B1: Product_Name | C1: Product_Category | D1: Product_Price | E1: Review_Score | F1: Review_Count | G1: Sales_Amount_January | H1: Sales_Amount_February | I1: Sales_Amount_March | J1: Sales_Amount_April | K1: Sales_Amount_May | L1: Sales_Amount_June | M1: Sales_Amount_July | N1: Sales_Amount_August | O1: Sales_Amount_September | P1: Sales_Amount_October | Q1: Sales_Amount_November | R1: Sales_Amount_December | S1: Annual_Revenue | T1: Average_Revenue_PerProduct | U1: Revenue_Contribution
A2: 1 | B2: Product_1 | C2: Clothing | D2: 190.4 | E2: 1.7 | F2: 220 | G2: =(ecommerce_sales_analysis!G2*ecommerce_sales_analysis!$D2) -> 91201.6 | H2: =(ecommerce_sales_analysis!H2*ecommerce_sales_analysis!$D2) -> 85489.6 | I2: =(ecommerce_sales_analysis!I2*ecommerce_sales_analysis!$D2) -> 17516.8 | J2: =(ecommerce_sales_analysis!J2*ecommerce_sales_analysis!$D2) -> 149273.6 | K2: =(ecommerce_sales_analysis!K2*ecommerce_sales_analysis!$D2) -> 115001.6 | L2: =(ecommerce_sales_analysis!L2*ecommerce_sales_analysis!$D2) -> 172121.6 | M2: =(ecommerce_sales_analysis!M2*ecommerce_sales_analysis!$D2) -> 84918.4 | N2: =(ecommerce_sales_analysis!N2*ecommerce_sales_analysis!$D2) -> 114811.2 | ... R2: =(ecommerce_sales_analysis!R2*ecommerce_sales_analysis!$D2) -> 58262.4 | S2: =SUM(G2:R2) -> 1222558.4 | T2: =AVERAGE(S2/12) -> 101879.87 | U2: =(S2/$S$1002)*100 -> 0.082122319
A3: 2 | B3: Product_2 | C3: Home & Kitchen | D3: 475.6 | E3: 3.2 | F3: 903 | G3: =(ecommerce_sales_analysis!G3*ecommerce_sales_analysis!$D3) -> 9987.6 | H3: =(ecommerce_sales_analysis!H3*ecommerce_sales_analysis!$D3) -> 470368.4 | I3: =(ecommerce_sales_analysis!I3*ecommerce_sales_analysis!$D3) -> 409491.6 | J3: =(ecommerce_sales_analysis!J3*ecommerce_sales_analysis!$D3) -> 410442.8 | K3: =(ecommerce_sales_analysis!K3*ecommerce_sales_analysis!$D3) -> 249214.4 | L3: =(ecommerce_sales_analysis!L3*ecommerce_sales_analysis!$D3) -> 60876.8 | M3: =(ecommerce_sales_analysis!M3*ecommerce_sales_analysis!$D3) -> 290116 | N3: =(ecommerce_sales_analysis!N3*ecommerce_sales_analysis!$D3) -> 207361.6 | ... R3: =(ecommerce_sales_analysis!R3*ecommerce_sales_analysis!$D3) -> 167886.8 | S3: =SUM(G3:R3) -> 2866441.2 | T3: =AVERAGE(S3/12) -> 238870.1 | U3: =(S3/$S$1002)*100 -> 0.19254606
A4: 3 | B4: Product_3 | C4: Toys | D4: 367.34 | E4: 4.5 | F4: 163 | G4: =(ecommerce_sales_analysis!G4*ecommerce_sales_analysis!$D4) -> 127834.32 | H4: =(ecommerce_sales_analysis!H4*ecommerce_sales_analysis!$D4) -> 204975.72 | I4: =(ecommerce_sales_analysis!I4*ecommerce_sales_analysis!$D4) -> 208281.78 | J4: =(ecommerce_sales_analysis!J4*ecommerce_sales_analysis!$D4) -> 52529.62 | K4: =(ecommerce_sales_analysis!K4*ecommerce_sales_analysis!$D4) -> 283219.14 | L4: =(ecommerce_sales_analysis!L4*ecommerce_sales_analysis!$D4) -> 150242.06 | M4: =(ecommerce_sales_analysis!M4*ecommerce_sales_analysis!$D4) -> 106528.6 | N4: =(ecommerce_sales_analysis!N4*ecommerce_sales_analysis!$D4) -> 304157.52 | ... R4: =(ecommerce_sales_analysis!R4*ecommerce_sales_analysis!$D4) -> 143997.28 | S4: =SUM(G4:R4) -> 2049757.2 | T4: =AVERAGE(S4/12) -> 170813.1 | U4: =(S4/$S$1002)*100 -> 0.13768734
A5: 4 | B5: Product_4 | C5: Toys | D5: 301.34 | E5: 3.9 | F5: 951 | G5: =(ecommerce_sales_analysis!G5*ecommerce_sales_analysis!$D5) -> 218471.5 | H5: =(ecommerce_sales_analysis!H5*ecommerce_sales_analysis!$D5) -> 204308.52 | I5: =(ecommerce_sales_analysis!I5*ecommerce_sales_analysis!$D5) -> 17779.06 | J5: =(ecommerce_sales_analysis!J5*ecommerce_sales_analysis!$D5) -> 4520.1 | K5: =(ecommerce_sales_analysis!K5*ecommerce_sales_analysis!$D5) -> 282355.58 | L5: =(ecommerce_sales_analysis!L5*ecommerce_sales_analysis!$D5) -> 126864.14 | M5: =(ecommerce_sales_analysis!M5*ecommerce_sales_analysis!$D5) -> 201897.8 | N5: =(ecommerce_sales_analysis!N5*ecommerce_sales_analysis!$D5) -> 281150.22 | ... R5: =(ecommerce_sales_analysis!R5*ecommerce_sales_analysis!$D5) -> 61172.02 | S5: =SUM(G5:R5) -> 1513329.5 | T5: =AVERAGE(S5/12) -> 126110.79 | U5: =(S5/$S$1002)*100 -> 0.10165414
A6: 5 | B6: Product_5 | C6: Books | D6: 82.23 | E6: 4.2 | F6: 220 | G6: =(ecommerce_sales_analysis!G6*ecommerce_sales_analysis!$D6) -> 56080.86 | H6: =(ecommerce_sales_analysis!H6*ecommerce_sales_analysis!$D6) -> 37085.73 | I6: =(ecommerce_sales_analysis!I6*ecommerce_sales_analysis!$D6) -> 53367.27 | J6: =(ecommerce_sales_analysis!J6*ecommerce_sales_analysis!$D6) -> 24751.23 | K6: =(ecommerce_sales_analysis!K6*ecommerce_sales_analysis!$D6) -> 50982.6 | L6: =(ecommerce_sales_analysis!L6*ecommerce_sales_analysis!$D6) -> 24093.39 | M6: =(ecommerce_sales_analysis!M6*ecommerce_sales_analysis!$D6) -> 33796.53 | N6: =(ecommerce_sales_analysis!N6*ecommerce_sales_analysis!$D6) -> 21215.34 | ... R6: =(ecommerce_sales_analysis!R6*ecommerce_sales_analysis!$D6) -> 21133.11 | S6: =SUM(G6:R6) -> 501109.62 | T6: =AVERAGE(S6/12) -> 41759.135 | U6: =(S6/$S$1002)*100 -> 0.033660792
A7: 6 | B7: Product_6 | C7: Toys | D7: 82.22 | E7: 3.6 | F7: 270 | G7: =(ecommerce_sales_analysis!G7*ecommerce_sales_analysis!$D7) -> 68571.48 | H7: =(ecommerce_sales_analysis!H7*ecommerce_sales_analysis!$D7) -> 23679.36 | I7: =(ecommerce_sales_analysis!I7*ecommerce_sales_analysis!$D7) -> 3124.36 | J7: =(ecommerce_sales_analysis!J7*ecommerce_sales_analysis!$D7) -> 34696.84 | K7: =(ecommerce_sales_analysis!K7*ecommerce_sales_analysis!$D7) -> 27050.38 | L7: =(ecommerce_sales_analysis!L7*ecommerce_sales_analysis!$D7) -> 20143.9 | M7: =(ecommerce_sales_analysis!M7*ecommerce_sales_analysis!$D7) -> 50483.08 | N7: =(ecommerce_sales_analysis!N7*ecommerce_sales_analysis!$D7) -> 80493.38 | ... R7: =(ecommerce_sales_analysis!R7*ecommerce_sales_analysis!$D7) -> 39876.7 | S7: =SUM(G7:R7) -> 530565.66 | T7: =AVERAGE(S7/12) -> 44213.805 | U7: =(S7/$S$1002)*100 -> 0.035639428
A8: 7 | B8: Product_7 | C8: Electronics | D8: 33.75 | E8: 3.8 | F8: 632 | G8: =(ecommerce_sales_analysis!G8*ecommerce_sales_analysis!$D8) -> 19068.75 | H8: =(ecommerce_sales_analysis!H8*ecommerce_sales_analysis!$D8) -> 4725 | I8: =(ecommerce_sales_analysis!I8*ecommerce_sales_analysis!$D8) -> 18191.25 | J8: =(ecommerce_sales_analysis!J8*ecommerce_sales_analysis!$D8) -> 8235 | K8: =(ecommerce_sales_analysis!K8*ecommerce_sales_analysis!$D8) -> 6345 | L8: =(ecommerce_sales_analysis!L8*ecommerce_sales_analysis!$D8) -> 23625 | M8: =(ecommerce_sales_analysis!M8*ecommerce_sales_analysis!$D8) -> 30240 | N8: =(ecommerce_sales_analysis!N8*ecommerce_sales_analysis!$D8) -> 32568.75 | ... R8: =(ecommerce_sales_analysis!R8*ecommerce_sales_analysis!$D8) -> 17415 | S8: =SUM(G8:R8) -> 178807.5 | T8: =AVERAGE(S8/12) -> 14900.625 | U8: =(S8/$S$1002)*100 -> 0.012010949
A9: 8 | B9: Product_8 | C9: Electronics | D9: 433.76 | E9: 4.4 | F9: 906 | G9: =(ecommerce_sales_analysis!G9*ecommerce_sales_analysis!$D9) -> 392552.8 | H9: =(ecommerce_sales_analysis!H9*ecommerce_sales_analysis!$D9) -> 36002.08 | I9: =(ecommerce_sales_analysis!I9*ecommerce_sales_analysis!$D9) -> 20820.48 | J9: =(ecommerce_sales_analysis!J9*ecommerce_sales_analysis!$D9) -> 401661.76 | K9: =(ecommerce_sales_analysis!K9*ecommerce_sales_analysis!$D9) -> 40773.44 | L9: =(ecommerce_sales_analysis!L9*ecommerce_sales_analysis!$D9) -> 240736.8 | M9: =(ecommerce_sales_analysis!M9*ecommerce_sales_analysis!$D9) -> 121452.8 | N9: =(ecommerce_sales_analysis!N9*ecommerce_sales_analysis!$D9) -> 44243.52 | ... R9: =(ecommerce_sales_analysis!R9*ecommerce_sales_analysis!$D9) -> 193023.2 | S9: =SUM(G9:R9) -> 2068601.4 | T9: =AVERAGE(S9/12) -> 172383.45 | U9: =(S9/$S$1002)*100 -> 0.13895316
A10: 9 | B10: Product_9 | C10: Electronics | D10: 302.55 | E10: 2 | F10: 848 | G10: =(ecommerce_sales_analysis!G10*ecommerce_sales_analysis!$D10) -> 244762.95 | H10: =(ecommerce_sales_analysis!H10*ecommerce_sales_analysis!$D10) -> 209667.15 | I10: =(ecommerce_sales_analysis!I10*ecommerce_sales_analysis!$D10) -> 126768.45 | J10: =(ecommerce_sales_analysis!J10*ecommerce_sales_analysis!$D10) -> 32070.3 | K10: =(ecommerce_sales_analysis!K10*ecommerce_sales_analysis!$D10) -> 186370.8 | L10: =(ecommerce_sales_analysis!L10*ecommerce_sales_analysis!$D10) -> 25716.75 | M10: =(ecommerce_sales_analysis!M10*ecommerce_sales_analysis!$D10) -> 12707.1 | N10: =(ecommerce_sales_analysis!N10*ecommerce_sales_analysis!$D10) -> 300129.6 | ... R10: =(ecommerce_sales_analysis!R10*ecommerce_sales_analysis!$D10) -> 214205.4 | S10: =SUM(G10:R10) -> 1717576.3 | T10: =AVERAGE(S10/12) -> 143131.36 | U10: =(S10/$S$1002)*100 -> 0.11537392
A11: 10 | B11: Product_10 | C11: Clothing | D11: 355.5 | E11: 3 | F11: 400 | G11: =(ecommerce_sales_analysis!G11*ecommerce_sales_analysis!$D11) -> 113404.5 | H11: =(ecommerce_sales_analysis!H11*ecommerce_sales_analysis!$D11) -> 138645 | I11: =(ecommerce_sales_analysis!I11*ecommerce_sales_analysis!$D11) -> 226098 | J11: =(ecommerce_sales_analysis!J11*ecommerce_sales_analysis!$D11) -> 30928.5 | K11: =(ecommerce_sales_analysis!K11*ecommerce_sales_analysis!$D11) -> 2488.5 | L11: =(ecommerce_sales_analysis!L11*ecommerce_sales_analysis!$D11) -> 197302.5 | M11: =(ecommerce_sales_analysis!M11*ecommerce_sales_analysis!$D11) -> 172417.5 | N11: =(ecommerce_sales_analysis!N11*ecommerce_sales_analysis!$D11) -> 201213 | ... R11: =(ecommerce_sales_analysis!R11*ecommerce_sales_analysis!$D11) -> 63634.5 | S11: =SUM(G11:R11) -> 1734484.5 | T11: =AVERAGE(S11/12) -> 144540.38 | U11: =(S11/$S$1002)*100 -> 0.11650968
A12: 11 | B12: Product_11 | C12: Toys | D12: 15.19 | E12: 1.9 | F12: 182 | G12: =(ecommerce_sales_analysis!G12*ecommerce_sales_analysis!$D12) -> 1898.75 | H12: =(ecommerce_sales_analysis!H12*ecommerce_sales_analysis!$D12) -> 8962.1 | I12: =(ecommerce_sales_analysis!I12*ecommerce_sales_analysis!$D12) -> 182.28 | J12: =(ecommerce_sales_analysis!J12*ecommerce_sales_analysis!$D12) -> 1944.32 | K12: =(ecommerce_sales_analysis!K12*ecommerce_sales_analysis!$D12) -> 1002.54 | L12: =(ecommerce_sales_analysis!L12*ecommerce_sales_analysis!$D12) -> 12774.79 | M12: =(ecommerce_sales_analysis!M12*ecommerce_sales_analysis!$D12) -> 9038.05 | N12: =(ecommerce_sales_analysis!N12*ecommerce_sales_analysis!$D12) -> 11665.92 | ... R12: =(ecommerce_sales_analysis!R12*ecommerce_sales_analysis!$D12) -> 5179.79 | S12: =SUM(G12:R12) -> 81509.54 | T12: =AVERAGE(S12/12) -> 6792.4617 | U12: =(S12/$S$1002)*100 -> 0.0054752006
A13: 12 | B13: Product_12 | C13: Health | D13: 485.11 | E13: 5 | F13: 991 | G13: =(ecommerce_sales_analysis!G13*ecommerce_sales_analysis!$D13) -> 133890.36 | H13: =(ecommerce_sales_analysis!H13*ecommerce_sales_analysis!$D13) -> 103813.54 | I13: =(ecommerce_sales_analysis!I13*ecommerce_sales_analysis!$D13) -> 480744.01 | J13: =(ecommerce_sales_analysis!J13*ecommerce_sales_analysis!$D13) -> 439509.66 | K13: =(ecommerce_sales_analysis!K13*ecommerce_sales_analysis!$D13) -> 240129.45 | L13: =(ecommerce_sales_analysis!L13*ecommerce_sales_analysis!$D13) -> 181431.14 | M13: =(ecommerce_sales_analysis!M13*ecommerce_sales_analysis!$D13) -> 466675.82 | N13: =(ecommerce_sales_analysis!N13*ecommerce_sales_analysis!$D13) -> 48511 | ... R13: =(ecommerce_sales_analysis!R13*ecommerce_sales_analysis!$D13) -> 64034.52 | S13: =SUM(G13:R13) -> 2891740.7 | T13: =AVERAGE(S13/12) -> 240978.39 | U13: =(S13/$S$1002)*100 -> 0.19424549
... A1001: 1000 | B1001: Product_1000 | C1001: Toys | D1001: 225.77 | E1001: 2.1 | F1001: 114 | G1001: =(ecommerce_sales_analysis!G1001*ecommerce_sales_analysis!$D1001) -> 200935.3 | H1001: =(ecommerce_sales_analysis!H1001*ecommerce_sales_analysis!$D1001) -> 203870.31 | I1001: =(ecommerce_sales_analysis!I1001*ecommerce_sales_analysis!$D1001) -> 221931.91 | J1001: =(ecommerce_sales_analysis!J1001*ecommerce_sales_analysis!$D1001) -> 173617.13 | K1001: =(ecommerce_sales_analysis!K1001*ecommerce_sales_analysis!$D1001) -> 30253.18 | L1001: =(ecommerce_sales_analysis!L1001*ecommerce_sales_analysis!$D1001) -> 158942.08 | M1001: =(ecommerce_sales_analysis!M1001*ecommerce_sales_analysis!$D1001) -> 146298.96 | N1001: =(ecommerce_sales_analysis!N1001*ecommerce_sales_analysis!$D1001) -> 90308 | ... R1001: =(ecommerce_sales_analysis!R1001*ecommerce_sales_analysis!$D1001) -> 24834.7 | S1001: =SUM(G1001:R1001) -> 1690114.2 | T1001: =AVERAGE(S1001/12) -> 140842.85 | U1001: =(S1001/$S$1002)*100 -> 0.11352922
A1002: Total Monthly Sales = | G1002: =SUM(G2:G1001) -> 1.2200073e+08 | H1002: =SUM(H2:H1001) -> 1.2561298e+08 | I1002: =SUM(I2:I1001) -> 1.2452215e+08 | J1002: =SUM(J2:J1001) -> 1.2663143e+08 | K1002: =SUM(K2:K1001) -> 1.2191532e+08 | L1002: =SUM(L2:L1001) -> 1.1962225e+08 | M1002: =SUM(M2:M1001) -> 1.2439792e+08 | N1002: =SUM(N2:N1001) -> 1.2308258e+08 | ... S1002: =SUM(S2:S1001) -> 1.4887042e+09 | T1002: =AVERAGE(S1002/12) -> 1.2405868e+08 | U1002: =(S1002/$S$1002)*100 -> 100
A1003: Average Monthly Sales = | G1003: =AVERAGE(G2:G1001) -> 122000.73 | H1003: =AVERAGE(H2:H1001) -> 125612.98 | I1003: =AVERAGE(I2:I1001) -> 124522.15 | J1003: =AVERAGE(J2:J1001) -> 126631.43 | K1003: =AVERAGE(K2:K1001) -> 121915.32 | L1003: =AVERAGE(L2:L1001) -> 119622.25 | M1003: =AVERAGE(M2:M1001) -> 124397.92 | N1003: =AVERAGE(N2:N1001) -> 123082.58 | ... S1003: =AVERAGE(S2:S1001) -> 1488704.2
B1007: KPI of Annual Ecommerce Sales
B1008: Total Annual Units Sold | D1008: 6019912
B1009: Total Revenue of the Year | D1009: 1.4887042e+09
B1010: Top 5 Products by Revenue | D1010: Product_306
D1011: Product_532
D1012: Product_53
D1013: Product_229
D1014: Product_391
